Workbook

Sheet RFA
A1: FOLLOW DOCUMENTS - RFA / THEO DÕI HỒ SƠ - RFA | I1: Current Date Ngày hiện tại | J1: =TODAY() -> 46309
A2: SECTION ICT / HẠNG MỤC ICT
A4: TT | B4: Package | C4: System Hệ | D4: Keyword Từ khóa | E4: Document Reference No. Tham chiếu hồ sơ số | F4: Deadline to responde Thời hạn trả lời | G4: Subject | H4: Tiêu đề | I4: Status Tình trạng | J4: Processing Time Thời gian xử lý | K4: Delay Chậm trễ | L4: Withdraw or Change (X) See notes Thu hồi hoặc Thay đổi (X) Xem ghi chú | M4: Documents Submission Hồ sơ đệ trình | O4: JCJV's Response Phản hồi của JCJV | Q4: Employer's Response Phản hồi của Chủ đầu tư | S4: Documents Submission Hồ sơ đệ trình | V4: JCJV's Response Phản hồi của JCJV | Y4: Employer's Response Phản hồi của Chủ đầu tư | AA4: Vietur Resubmission Status Tình trạng đệ trình lại hồ sơ | AE4: Notes Ghi chú
M5: Official Chính thức | N5: Internal Nội bộ | O5: Official Chính thức | P5: Internal Nội bộ | Q5: Official Chính thức | R5: Status Trạng thái | S5: Sub. Date (Soft copy) Ngày đệ trình (bản mềm) | T5: Sub. Date (by Email) Ngày đệ trình (bằng Email) | U5: Sub. Date (Hard copy) Ngày đệ trình (bản cứng) | V5: Response Date Ngày phản hồi | W5: Submit Date Ngày phát hành | X5: Signed by Đã ký bởi | Y5: Response Date Ngày phản hồi (by Email) | Z5: Submit Date (Hard copy) Ngày phát hành (bản cứng) | AA5: Deadline to resubmit Hạn chót đệ trình lại | AB5: Actual resubmission Date Ngày đệ trình thực tế | AC5: Resubmission Status Assessment Đánh giá tình trạng đệ trình lại | AD5: Delayed Days Ngày chậm trễ | AG5: Base Reference Tham chiếu cơ sở | AH5: Latest Revision Phiên bản cuối | AI5: Need Submisson Cần đệ trình lại
A7: =A6+1 -> 1 | B7: =MID(E7, FIND("-", E7) + 1, 4) -> 5.10 | C7: FAS | D7: MAS | E7: LTIA-5.10-VIETUR-70000-RFA-MAS-0088 | F7: =IF($U7=0,$T7+22,$U7+21) -> 45308 | G7: Request for approval material cable fire resistant shield for fire alarm system (Belden) | H7: Đề nghị phê duyệt vật liệu cáp chống cháy cho hệ thống báo cháy (Belden) | I7: C | J7: =MAX(0, IF(ISBLANK($W7), _xlfn.DAYS($J$1,$U7), _xlfn.DAYS($W7,$U7))) -> 15 | K7: =IF(($J7-21)>0,$J7-21,0) -> 0 | M7: Link | N7: Link | O7: Link | P7: Link | Q7: Link | R7: C | S7: 45287 | T7: 45287 | U7: 45287 | V7: 45293 | W7: 45302 | X7: Mr Phong + Shimada | Y7: 45308 | Z7: 45309 | AA7: =IF(AND($R7="",$I7=""),"",IF(OR($R7="B",$R7="C"),IF($Z7<>"",$Z7+7,IF($Y7<>"",$Y7+8,"")),IF($R7="",IF(OR($I7="B",$I7="C"),IF($W7<>"",$W7+7,IF($V7<>"",$V7+8,""))),""))) -> 45316 | AB7: 45426 | AC7: =IF(OR($R7="B",$R7="C"),IF($AA7="","",IF($AB7="",IF($AA7>=$J$1,"In progress","Not submit yet"),IF($AA7>=$AB7,"Timely Response","Late Resubmission"))),"") -> Late Resubmission | AD7: =IF(AC7="Late Resubmission",IF(AB7="","",AB7-AA7),IF(AC7="Not submit yet",IF(AA7="","",$J$1-AA7),"")) -> 110 | AG7: =IF(AND(RIGHT($E7,1)>="A",RIGHT($E7,1)<="Z"),LEFT($E7,LEN($E7)-1),$E7) -> LTIA-5.10-VIETUR-70000-RFA-MAS-0088 | AH7: {=$E7=_xlfn.XLOOKUP( AG7, _xlfn._xlws.FILTER($AG$7:$AG$4572,$L$7:$L$4572<>"X"), _xlfn._xlws.FILTER($E$7:$E$4572,$L$7:$L$4572<>"X"), "", 0, -1 )} -> FALSE | AI7: =IF($AH7,IF(OR($R7="B",$R7="C"),"YES",IF($R7="",IF(OR($I7="B",$I7="C"),"YES",""),"")),"")
A8: =A7+1 -> 2 | B8: =MID(E8, FIND("-", E8) + 1, 4) -> 5.10 | C8: FAS | D8: MAS | E8: LTIA-5.10-VIETUR-70000-RFA-MAS-0093 | F8: =IF($U8=0,$T8+22,$U8+21) -> 45309 | G8: Request for approval of conduit and accessories for fire alarm system (Cat Van Loi) | H8: Đề nghị phê duyệt vật liệu ống thép luồn dây và phụ kiện cho hệ thống báo cháy (Cát Vạn Lợi) | I8: A | J8: =MAX(0, IF(ISBLANK($W8), _xlfn.DAYS($J$1,$U8), _xlfn.DAYS($W8,$U8))) -> 5 | K8: =IF(($J8-21)>0,$J8-21,0) -> 0 | M8: Link | N8: Link | O8: Link | P8: Link | Q8: Link | R8: A | S8: 45288 | T8: 45288 | U8: 45288 | V8: 45655 | W8: 45293 | X8: Mr Hưởng + Phong | Y8: 45299 | Z8: 45299 | AA8: =IF(AND($R8="",$I8=""),"",IF(OR($R8="B",$R8="C"),IF($Z8<>"",$Z8+7,IF($Y8<>"",$Y8+8,"")),IF($R8="",IF(OR($I8="B",$I8="C"),IF($W8<>"",$W8+7,IF($V8<>"",$V8+8,""))),""))) | AC8: =IF(OR($R8="B",$R8="C"),IF($AA8="","",IF($AB8="",IF($AA8>=$J$1,"In progress","Not submit yet"),IF($AA8>=$AB8,"Timely Response","Late Resubmission"))),"") | AD8: =IF(AC8="Late Resubmission",IF(AB8="","",AB8-AA8),IF(AC8="Not submit yet",IF(AA8="","",$J$1-AA8),"")) | AG8: =IF(AND(RIGHT($E8,1)>="A",RIGHT($E8,1)<="Z"),LEFT($E8,LEN($E8)-1),$E8) -> LTIA-5.10-VIETUR-70000-RFA-MAS-0093 | AH8: {=$E8=_xlfn.XLOOKUP( AG8, _xlfn._xlws.FILTER($AG$7:$AG$4572,$L$7:$L$4572<>"X"), _xlfn._xlws.FILTER($E$7:$E$4572,$L$7:$L$4572<>"X"), "", 0, -1 )} -> TRUE | AI8: =IF($AH8,IF(OR($R8="B",$R8="C"),"YES",IF($R8="",IF(OR($I8="B",$I8="C"),"YES",""),"")),"")
A9: =A8+1 -> 3 | B9: =MID(E9, FIND("-", E9) + 1, 4) -> 5.10 | C9: SCS | D9: MAS | E9: LTIA-5.10-VIETUR-70000-RFA-MAS-0116 | F9: =IF($U9=0,$T9+22,$U9+21) -> 45320 | G9: Request for approval of Material for Cable Tray & Accessories - Hai Nam | H9: Đề nghị phê duyệt vật tư cho Máng cáp & Phụ Kiện - Hải Nam | I9: A | J9: =MAX(0, IF(ISBLANK($W9), _xlfn.DAYS($J$1,$U9), _xlfn.DAYS($W9,$U9))) -> 16 | K9: =IF(($J9-21)>0,$J9-21,0) -> 0 | M9: Link | N9: Link | O9: Link | P9: Link | Q9: Link | R9: A | S9: 45299 | T9: 45299 | U9: 45299 | V9: 45303 | W9: 45315 | X9: Mr Phong + Tiệp | Y9: 45317 | Z9: 45317 | AA9: =IF(AND($R9="",$I9=""),"",IF(OR($R9="B",$R9="C"),IF($Z9<>"",$Z9+7,IF($Y9<>"",$Y9+8,"")),IF($R9="",IF(OR($I9="B",$I9="C"),IF($W9<>"",$W9+7,IF($V9<>"",$V9+8,""))),""))) | AC9: =IF(OR($R9="B",$R9="C"),IF($AA9="","",IF($AB9="",IF($AA9>=$J$1,"In progress","Not submit yet"),IF($AA9>=$AB9,"Timely Response","Late Resubmission"))),"") | AD9: =IF(AC9="Late Resubmission",IF(AB9="","",AB9-AA9),IF(AC9="Not submit yet",IF(AA9="","",$J$1-AA9),"")) | AG9: =IF(AND(RIGHT($E9,1)>="A",RIGHT($E9,1)<="Z"),LEFT($E9,LEN($E9)-1),$E9) -> LTIA-5.10-VIETUR-70000-RFA-MAS-0116 | AH9: {=$E9=_xlfn.XLOOKUP( AG9, _xlfn._xlws.FILTER($AG$7:$AG$4572,$L$7:$L$4572<>"X"), _xlfn._xlws.FILTER($E$7:$E$4572,$L$7:$L$4572<>"X"), "", 0, -1 )} -> TRUE | AI9: =IF($AH9,IF(OR($R9="B",$R9="C"),"YES",IF($R9="",IF(OR($I9="B",$I9="C"),"YES",""),"")),"")
A10: =A9+1 -> 4 | B10: =MID(E10, FIND("-", E10) + 1, 4) -> 5.10 | C10: SCS | D10: MAS | E10: LTIA-5.10-VIETUR-70000-RFA-MAS-0158 | F10: =IF($U10=0,$T10+22,$U10+21) -> 45337 | G10: Request for approval of ICT cable - ELV System | H10: Đề nghị phê duyệt vật tư cáp điện nhẹ - Hệ thống điện nhẹ | I10: C | J10: =MAX(0, IF(ISBLANK($W10), _xlfn.DAYS($J$1,$U10), _xlfn.DAYS($W10,$U10))) -> 11 | K10: =IF(($J10-21)>0,$J10-21,0) -> 0 | M10: Link | N10: Link | O10: Link | P10: Link | Q10: Link | R10: C | S10: 45315 | T10: 45315 | U10: 45316 | V10: 45322 | W10: 45327 | X10: Mr Hưởng + Tiệp | Y10: 45329 | Z10: 45329 | AA10: =IF(AND($R10="",$I10=""),"",IF(OR($R10="B",$R10="C"),IF($Z10<>"",$Z10+7,IF($Y10<>"",$Y10+8,"")),IF($R10="",IF(OR($I10="B",$I10="C"),IF($W10<>"",$W10+7,IF($V10<>"",$V10+8,""))),""))) -> 45336 | AB10: 45525 | AC10: =IF(OR($R10="B",$R10="C"),IF($AA10="","",IF($AB10="",IF($AA10>=$J$1,"In progress","Not submit yet"),IF($AA10>=$AB10,"Timely Response","Late Resubmission"))),"") -> Late Resubmission | AD10: =IF(AC10="Late Resubmission",IF(AB10="","",AB10-AA10),IF(AC10="Not submit yet",IF(AA10="","",$J$1-AA10),"")) -> 189 | AG10: =IF(AND(RIGHT($E10,1)>="A",RIGHT($E10,1)<="Z"),LEFT($E10,LEN($E10)-1),$E10) -> LTIA-5.10-VIETUR-70000-RFA-MAS-0158 | AH10: {=$E10=_xlfn.XLOOKUP( AG10, _xlfn._xlws.FILTER($AG$7:$AG$4572,$L$7:$L$4572<>"X"), _xlfn._xlws.FILTER($E$7:$E$4572,$L$7:$L$4572<>"X"), "", 0, -1 )} -> FALSE | AI10: =IF($AH10,IF(OR($R10="B",$R10="C"),"YES",IF($R10="",IF(OR($I10="B",$I10="C"),"YES",""),"")),"")
A11: =A10+1 -> 5 | B11: =MID(E11, FIND("-", E11) + 1, 4) -> 5.10 | C11: FAS | D11: MSS | E11: LTIA-5.10-VIETUR-72160-RFA-MSS-0082 | F11: =IF($U11=0,$T11+22,$U11+21) -> 45411 | G11: Request for approval for method statement of fire alarm system installation | H11: Đề nghị phê duyệt thuyết minh biện pháp thi công hệ thống báo cháy | I11: B | J11: =MAX(0, IF(ISBLANK($W11), _xlfn.DAYS($J$1,$U11), _xlfn.DAYS($W11,$U11))) -> 8 | K11: =IF(($J11-21)>0,$J11-21,0) -> 0 | M11: Link | N11: Link | O11: Link | P11: Link | Q11: Link | R11: B | S11: 45387 | T11: 45387 | U11: 45390 | V11: 45398 | W11: 45398 | X11: Mr Phụng + Phong | Y11: 45441 | Z11: 45442 | AA11: =IF(AND($R11="",$I11=""),"",IF(OR($R11="B",$R11="C"),IF($Z11<>"",$Z11+7,IF($Y11<>"",$Y11+8,"")),IF($R11="",IF(OR($I11="B",$I11="C"),IF($W11<>"",$W11+7,IF($V11<>"",$V11+8,""))),""))) -> 45449 | AB11: 45492 | AC11: =IF(OR($R11="B",$R11="C"),IF($AA11="","",IF($AB11="",IF($AA11>=$J$1,"In progress","Not submit yet"),IF($AA11>=$AB11,"Timely Response","Late Resubmission"))),"") -> Late Resubmission | AD11: =IF(AC11="Late Resubmission",IF(AB11="","",AB11-AA11),IF(AC11="Not submit yet",IF(AA11="","",$J$1-AA11),"")) -> 43 | AG11: =IF(AND(RIGHT($E11,1)>="A",RIGHT($E11,1)<="Z"),LEFT($E11,LEN($E11)-1),$E11) -> LTIA-5.10-VIETUR-72160-RFA-MSS-0082 | AH11: {=$E11=_xlfn.XLOOKUP( AG11, _xlfn._xlws.FILTER($AG$7:$AG$4572,$L$7:$L$4572<>"X"), _xlfn._xlws.FILTER($E$7:$E$4572,$L$7:$L$4572<>"X"), "", 0, -1 )} -> FALSE | AI11: =IF($AH11,IF(OR($R11="B",$R11="C"),"YES",IF($R11="",IF(OR($I11="B",$I11="C"),"YES",""),"")),"")
A12: =A11+1 -> 6 | B12: =MID(E12, FIND("-", E12) + 1, 4) -> 5.10 | C12: FAS | D12: MAS | E12: LTIA-5.10-VIETUR-70000-RFA-MAS-0208 | F12: =IF($U12=0,$T12+22,$U12+21) -> 45414 | G12: Request for approval of fire alarm equipment for fire alarm system | H12: Đề nghị phê duyệt thiết bị báo cháy cho hệ thống báo cháy | I12: B | J12: =MAX(0, IF(ISBLANK($W12), _xlfn.DAYS($J$1,$U12), _xlfn.DAYS($W12,$U12))) -> 34 | K12: =IF(($J12-21)>0,$J12-21,0) -> 13 | M12: Link | N12: Link | O12: Link | P12: Link | Q12: Link | R12: B | S12: 45392 | T12: 45392 | U12: 45393 | V12: 45427 | W12: 45427 | X12: Mr Phong + Shimada | Y12: 45456 | Z12: 45456 | AA12: =IF(AND($R12="",$I12=""),"",IF(OR($R12="B",$R12="C"),IF($Z12<>"",$Z12+7,IF($Y12<>"",$Y12+8,"")),IF($R12="",IF(OR($I12="B",$I12="C"),IF($W12<>"",$W12+7,IF($V12<>"",$V12+8,""))),""))) -> 45463 | AB12: 45512 | AC12: =IF(OR($R12="B",$R12="C"),IF($AA12="","",IF($AB12="",IF($AA12>=$J$1,"In progress","Not submit yet"),IF($AA12>=$AB12,"Timely Response","Late Resubmission"))),"") -> Late Resubmission | AD12: =IF(AC12="Late Resubmission",IF(AB12="","",AB12-AA12),IF(AC12="Not submit yet",IF(AA12="","",$J$1-AA12),"")) -> 49 | AG12: =IF(AND(RIGHT($E12,1)>="A",RIGHT($E12,1)<="Z"),LEFT($E12,LEN($E12)-1),$E12) -> LTIA-5.10-VIETUR-70000-RFA-MAS-0208 | AH12: {=$E12=_xlfn.XLOOKUP( AG12, _xlfn._xlws.FILTER($AG$7:$AG$4572,$L$7:$L$4572<>"X"), _xlfn._xlws.FILTER($E$7:$E$4572,$L$7:$L$4572<>"X"), "", 0, -1 )} -> FALSE | AI12: =IF($AH12,IF(OR($R12="B",$R12="C"),"YES",IF($R12="",IF(OR($I12="B",$I12="C"),"YES",""),"")),"")
A13: =A12+1 -> 7 | B13: =MID(E13, FIND("-", E13) + 1, 4) -> 5.10 | C13: MCS | D13: MAS | E13: LTIA-5.10-VIETUR-70000-RFA-MAS-0219 | F13: =IF($U13=0,$T13+22,$U13+21) -> 45419 | G13: Request for approval of list material and equipment for master clock system | H13: Đề nghị phê duyệt danh mục vật tư và thiết bị cho hệ thống đồng hồ chủ | I13: B | J13: =MAX(0, IF(ISBLANK($W13), _xlfn.DAYS($J$1,$U13), _xlfn.DAYS($W13,$U13))) -> 22 | K13: =IF(($J13-21)>0,$J13-21,0) -> 1 | M13: Link | N13: Link | O13: Link | P13: Link | Q13: Link | R13: B | S13: 45398 | T13: 45398 | U13: 45398 | V13: 45420 | W13: 45420 | X13: Mr Phong + Shimada | Y13: 45440 | Z13: 45441 | AA13: =IF(AND($R13="",$I13=""),"",IF(OR($R13="B",$R13="C"),IF($Z13<>"",$Z13+7,IF($Y13<>"",$Y13+8,"")),IF($R13="",IF(OR($I13="B",$I13="C"),IF($W13<>"",$W13+7,IF($V13<>"",$V13+8,""))),""))) -> 45448 | AB13: 45457 | AC13: =IF(OR($R13="B",$R13="C"),IF($AA13="","",IF($AB13="",IF($AA13>=$J$1,"In progress","Not submit yet"),IF($AA13>=$AB13,"Timely Response","Late Resubmission"))),"") -> Late Resubmission | AD13: =IF(AC13="Late Resubmission",IF(AB13="","",AB13-AA13),IF(AC13="Not submit yet",IF(AA13="","",$J$1-AA13),"")) -> 9 | AG13: =IF(AND(RIGHT($E13,1)>="A",RIGHT($E13,1)<="Z"),LEFT($E13,LEN($E13)-1),$E13) -> LTIA-5.10-VIETUR-70000-RFA-MAS-0219 | AH13: {=$E13=_xlfn.XLOOKUP( AG13, _xlfn._xlws.FILTER($AG$7:$AG$4572,$L$7:$L$4572<>"X"), _xlfn._xlws.FILTER($E$7:$E$4572,$L$7:$L$4572<>"X"), "", 0, -1 )} -> FALSE | AI13: =IF($AH13,IF(OR($R13="B",$R13="C"),"YES",IF($R13="",IF(OR($I13="B",$I13="C"),"YES",""),"")),"")
A14: =A13+1 -> 8 | B14: =MID(E14, FIND("-", E14) + 1, 4) -> 5.10 | C14: FAS | D14: MAS | E14: LTIA-5.10-VIETUR-70000-RFA-MAS-0088A | F14: =IF($U14=0,$T14+22,$U14+21) -> 45447 | G14: Request for approval material cable fire resistant shield for fire alarm system (Belden) | H14: Đề nghị phê duyệt vật liệu cáp chống cháy cho hệ thống báo cháy (Belden) | I14: C | J14: =MAX(0, IF(ISBLANK($W14), _xlfn.DAYS($J$1,$U14), _xlfn.DAYS($W14,$U14))) -> 29 | K14: =IF(($J14-21)>0,$J14-21,0) -> 8 | M14: Link | N14: Link | O14: Link | P14: Link | Q14: Link | R14: C | S14: 45426 | T14: 45426 | U14: 45426 | V14: 45454 | W14: 45455 | X14: Mr Phong + Shimada | Y14: 45456 | Z14: 45456 | AA14: =IF(AND($R14="",$I14=""),"",IF(OR($R14="B",$R14="C"),IF($Z14<>"",$Z14+7,IF($Y14<>"",$Y14+8,"")),IF($R14="",IF(OR($I14="B",$I14="C"),IF($W14<>"",$W14+7,IF($V14<>"",$V14+8,""))),""))) -> 45463 | AC14: =IF(OR($R14="B",$R14="C"),IF($AA14="","",IF($AB14="",IF($AA14>=$J$1,"In progress","Not submit yet"),IF($AA14>=$AB14,"Timely Response","Late Resubmission"))),"") -> Not submit yet | AD14: =IF(AC14="Late Resubmission",IF(AB14="","",AB14-AA14),IF(AC14="Not submit yet",IF(AA14="","",$J$1-AA14),"")) -> 846 | AG14: =IF(AND(RIGHT($E14,1)>="A",RIGHT($E14,1)<="Z"),LEFT($E14,LEN($E14)-1),$E14) -> LTIA-5.10-VIETUR-70000-RFA-MAS-0088 | AH14: {=$E14=_xlfn.XLOOKUP( AG14, _xlfn._xlws.FILTER($AG$7:$AG$4572,$L$7:$L$4572<>"X"), _xlfn._xlws.FILTER($E$7:$E$4572,$L$7:$L$4572<>"X"), "", 0, -1 )} -> TRUE | AI14: =IF($AH14,IF(OR($R14="B",$R14="C"),"YES",IF($R14="",IF(OR($I14="B",$I14="C"),"YES",""),"")),"") -> YES
A15: =A14+1 -> 9 | B15: =MID(E15, FIND("-", E15) + 1, 4) -> 5.10 | C15: FAS | D15: MAS | E15: LTIA-5.10-VIETUR-70000-RFA-MAS-0248 | F15: =IF($U15=0,$T15+22,$U15+21) -> 45449 | G15: Request for approval material for accessories of GI conduit (EMT) for fire alarm system (Cat Van Loi) | H15: Đề nghị phê duyệt vật tư về phụ kiện của ống thép GI luồn dây (EMT) cho hệ thống báo cháy (Cat Van Loi) | I15: C | J15: =MAX(0, IF(ISBLANK($W15), _xlfn.DAYS($J$1,$U15), _xlfn.DAYS($W15,$U15))) -> 20 | K15: =IF(($J15-21)>0,$J15-21,0) -> 0 | M15: Link | N15: Link | O15: Link | P15: Link | Q15: Link | R15: C | S15: 45428 | T15: 45428 | U15: 45428 | V15: 45447 | W15: 45448 | X15: Mr Hưởng + Shimada | Y15: 45488 | Z15: 45491 | AA15: =IF(AND($R15="",$I15=""),"",IF(OR($R15="B",$R15="C"),IF($Z15<>"",$Z15+7,IF($Y15<>"",$Y15+8,"")),IF($R15="",IF(OR($I15="B",$I15="C"),IF($W15<>"",$W15+7,IF($V15<>"",$V15+8,""))),""))) -> 45498 | AC15: =IF(OR($R15="B",$R15="C"),IF($AA15="","",IF($AB15="",IF($AA15>=$J$1,"In progress","Not submit yet"),IF($AA15>=$AB15,"Timely Response","Late Resubmission"))),"") -> Not submit yet | AD15: =IF(AC15="Late Resubmission",IF(AB15="","",AB15-AA15),IF(AC15="Not submit yet",IF(AA15="","",$J$1-AA15),"")) -> 811 | AG15: =IF(AND(RIGHT($E15,1)>="A",RIGHT($E15,1)<="Z"),LEFT($E15,LEN($E15)-1),$E15) -> LTIA-5.10-VIETUR-70000-RFA-MAS-0248 | AH15: {=$E15=_xlfn.XLOOKUP( AG15, _xlfn._xlws.FILTER($AG$7:$AG$4572,$L$7:$L$4572<>"X"), _xlfn._xlws.FILTER($E$7:$E$4572,$L$7:$L$4572<>"X"), "", 0, -1 )} -> TRUE | AI15: =IF($AH15,IF(OR($R15="B",$R15="C"),"YES",IF($R15="",IF(OR($I15="B",$I15="C"),"YES",""),"")),"") -> YES
A16: =A15+1 -> 10 | B16: =MID(E16, FIND("-", E16) + 1, 4) -> 5.10 | C16: SCS | D16: MAS | E16: LTIA-5.10-VIETUR-70000-RFA-MAS-0258 | F16: =IF($U16=0,$T16+22,$U16+21) -> 45460 | G16: Request for approval Material of structured cabling system (SCS) | H16: Đề nghị phê duyệt vật tư hệ thống cấu trúc mạng | I16: C | J16: =MAX(0, IF(ISBLANK($W16), _xlfn.DAYS($J$1,$U16), _xlfn.DAYS($W16,$U16))) -> 16 | K16: =IF(($J16-21)>0,$J16-21,0) -> 0 | M16: Link | N16: Link | O16: Link | P16: Link | Q16: Link | R16: C | S16: 45437 | T16: 45437 | U16: 45439 | V16: 45455 | W16: 45455 | X16: Mr Phong + Shimada | Y16: 45460 | Z16: 45461 | AA16: =IF(AND($R16="",$I16=""),"",IF(OR($R16="B",$R16="C"),IF($Z16<>"",$Z16+7,IF($Y16<>"",$Y16+8,"")),IF($R16="",IF(OR($I16="B",$I16="C"),IF($W16<>"",$W16+7,IF($V16<>"",$V16+8,""))),""))) -> 45468 | AB16: 45553 | AC16: =IF(OR($R16="B",$R16="C"),IF($AA16="","",IF($AB16="",IF($AA16>=$J$1,"In progress","Not submit yet"),IF($AA16>=$AB16,"Timely Response","Late Resubmission"))),"") -> Late Resubmission | AD16: =IF(AC16="Late Resubmission",IF(AB16="","",AB16-AA16),IF(AC16="Not submit yet",IF(AA16="","",$J$1-AA16),"")) -> 85 | AG16: =IF(AND(RIGHT($E16,1)>="A",RIGHT($E16,1)<="Z"),LEFT($E16,LEN($E16)-1),$E16) -> LTIA-5.10-VIETUR-70000-RFA-MAS-0258 | AH16: {=$E16=_xlfn.XLOOKUP( AG16, _xlfn._xlws.FILTER($AG$7:$AG$4572,$L$7:$L$4572<>"X"), _xlfn._xlws.FILTER($E$7:$E$4572,$L$7:$L$4572<>"X"), "", 0, -1 )} -> FALSE | AI16: =IF($AH16,IF(OR($R16="B",$R16="C"),"YES",IF($R16="",IF(OR($I16="B",$I16="C"),"YES",""),"")),"")
A17: =A16+1 -> 11 | B17: =MID(E17, FIND("-", E17) + 1, 4) -> 5.10 | C17: FAS | D17: MAS | E17: LTIA-5.10-VIETUR-70000-RFA-MAS-0265 | F17: =IF($U17=0,$T17+22,$U17+21) -> 45467 | G17: Request for approval of conduit and accessories for fire fighting alarm system Hung Phat brand | H17: Đề nghị phê duyệt vật tư ống thép luồn dây và phụ kiện cho hệ thống báo cháy nhãn hiệu Hưng Phát | I17: A | J17: =MAX(0, IF(ISBLANK($W17), _xlfn.DAYS($J$1,$U17), _xlfn.DAYS($W17,$U17))) -> 9 | K17: =IF(($J17-21)>0,$J17-21,0) -> 0 | M17: Link | N17: Link | O17: Link | P17: Link | Q17: Link | R17: A | S17: 45446 | T17: 45446 | U17: 45446 | V17: 45455 | W17: 45455 | X17: Mr Phong + Shimada | Y17: 45464 | Z17: 45465 | AA17: =IF(AND($R17="",$I17=""),"",IF(OR($R17="B",$R17="C"),IF($Z17<>"",$Z17+7,IF($Y17<>"",$Y17+8,"")),IF($R17="",IF(OR($I17="B",$I17="C"),IF($W17<>"",$W17+7,IF($V17<>"",$V17+8,""))),""))) | AC17: =IF(OR($R17="B",$R17="C"),IF($AA17="","",IF($AB17="",IF($AA17>=$J$1,"In progress","Not submit yet"),IF($AA17>=$AB17,"Timely Response","Late Resubmission"))),"") | AD17: =IF(AC17="Late Resubmission",IF(AB17="","",AB17-AA17),IF(AC17="Not submit yet",IF(AA17="","",$J$1-AA17),"")) | AG17: =IF(AND(RIGHT($E17,1)>="A",RIGHT($E17,1)<="Z"),LEFT($E17,LEN($E17)-1),$E17) -> LTIA-5.10-VIETUR-70000-RFA-MAS-0265 | AH17: {=$E17=_xlfn.XLOOKUP( AG17, _xlfn._xlws.FILTER($AG$7:$AG$4572,$L$7:$L$4572<>"X"), _xlfn._xlws.FILTER($E$7:$E$4572,$L$7:$L$4572<>"X"), "", 0, -1 )} -> TRUE | AI17: =IF($AH17,IF(OR($R17="B",$R17="C"),"YES",IF($R17="",IF(OR($I17="B",$I17="C"),"YES",""),"")),"")
A18: =A17+1 -> 12 | B18: =MID(E18, FIND("-", E18) + 1, 4) -> 5.10 | C18: MCS | D18: MAS | E18: LTIA-5.10-VIETUR-70000-RFA-MAS-0219A | F18: =IF($U18=0,$T18+22,$U18+21) -> 45474 | G18: Request for approval of list material and equipment for master clock system | H18: Đề nghị phê duyệt danh mục vật tư và thiết bị cho hệ thống đồng hồ chủ | I18: A | J18: =MAX(0, IF(ISBLANK($W18), _xlfn.DAYS($J$1,$U18), _xlfn.DAYS($W18,$U18))) -> 15 | K18: =IF(($J18-21)>0,$J18-21,0) -> 0 | M18: Link | N18: Link | O18: Link | P18: Link | Q18: Link | R18: A | S18: 45450 | T18: 45450 | U18: 45453 | V18: 45467 | W18: 45468 | X18: Mr Phong + Shimada | Y18: 45469 | Z18: 45470 | AA18: =IF(AND($R18="",$I18=""),"",IF(OR($R18="B",$R18="C"),IF($Z18<>"",$Z18+7,IF($Y18<>"",$Y18+8,"")),IF($R18="",IF(OR($I18="B",$I18="C"),IF($W18<>"",$W18+7,IF($V18<>"",$V18+8,""))),""))) | AB18: 45973 | AC18: =IF(OR($R18="B",$R18="C"),IF($AA18="","",IF($AB18="",IF($AA18>=$J$1,"In progress","Not submit yet"),IF($AA18>=$AB18,"Timely Response","Late Resubmission"))),"") | AD18: =IF(AC18="Late Resubmission",IF(AB18="","",AB18-AA18),IF(AC18="Not submit yet",IF(AA18="","",$J$1-AA18),"")) | AG18: =IF(AND(RIGHT($E18,1)>="A",RIGHT($E18,1)<="Z"),LEFT($E18,LEN($E18)-1),$E18) -> LTIA-5.10-VIETUR-70000-RFA-MAS-0219 | AH18: {=$E18=_xlfn.XLOOKUP( AG18, _xlfn._xlws.FILTER($AG$7:$AG$4572,$L$7:$L$4572<>"X"), _xlfn._xlws.FILTER($E$7:$E$4572,$L$7:$L$4572<>"X"), "", 0, -1 )} -> FALSE | AI18: =IF($AH18,IF(OR($R18="B",$R18="C"),"YES",IF($R18="",IF(OR($I18="B",$I18="C"),"YES",""),"")),"")
A19: =A18+1 -> 13 | B19: =MID(E19, FIND("-", E19) + 1, 4) -> 5.10 | C19: IMM | D19: MAS | E19: LTIA-5.10-VIETUR-70000-RFA-MAS-0277 | F19: =IF($U19=0,$T19+22,$U19+21) -> 45475 | G19: Request for approval of equipment and accessories for Immigration system (IMM) | H19: Đề nghị phê duyệt thiết bị và phụ kiện cho hệ thống Công an cửa khẩu (IMM) | I19: B | J19: =MAX(0, IF(ISBLANK($W19), _xlfn.DAYS($J$1,$U19), _xlfn.DAYS($W19,$U19))) -> 24 | K19: =IF(($J19-21)>0,$J19-21,0) -> 3 | M19: Link | N19: Link | O19: Link | P19: Link | Q19: Link | R19: B | S19: 45454 | T19: 45454 | U19: 45454 | V19: 45471 | W19: 45478 | X19: Mr Phong + Shimada | Y19: 45632 | Z19: 45635 | AA19: =IF(AND($R19="",$I19=""),"",IF(OR($R19="B",$R19="C"),IF($Z19<>"",$Z19+7,IF($Y19<>"",$Y19+8,"")),IF($R19="",IF(OR($I19="B",$I19="C"),IF($W19<>"",$W19+7,IF($V19<>"",$V19+8,""))),""))) -> 45642 | AB19: 45883 | AC19: =IF(OR($R19="B",$R19="C"),IF($AA19="","",IF($AB19="",IF($AA19>=$J$1,"In progress","Not submit yet"),IF($AA19>=$AB19,"Timely Response","Late Resubmission"))),"") -> Late Resubmission | AD19: =IF(AC19="Late Resubmission",IF(AB19="","",AB19-AA19),IF(AC19="Not submit yet",IF(AA19="","",$J$1-AA19),"")) -> 241 | AG19: =IF(AND(RIGHT($E19,1)>="A",RIGHT($E19,1)<="Z"),LEFT($E19,LEN($E19)-1),$E19) -> LTIA-5.10-VIETUR-70000-RFA-MAS-0277 | AH19: {=$E19=_xlfn.XLOOKUP( AG19, _xlfn._xlws.FILTER($AG$7:$AG$4572,$L$7:$L$4572<>"X"), _xlfn._xlws.FILTER($E$7:$E$4572,$L$7:$L$4572<>"X"), "", 0, -1 )} -> FALSE | AI19: =IF($AH19,IF(OR($R19="B",$R19="C"),"YES",IF($R19="",IF(OR($I19="B",$I19="C"),"YES",""),"")),"")
A20: =A19+1 -> 14 | B20: =MID(E20, FIND("-", E20) + 1, 4) -> 5.10 | C20: SCS | D20: MAS | E20: LTIA-5.10-VIETUR-70000-RFA-MAS-0271 | F20: =IF($U20=0,$T20+22,$U20+21) -> 45478 | G20: Request for approval of ICT cable of Item PMR, PAS & IMM - ELV system | H20: Đề nghị phê duyệt vật tư cáp điện nhẹ của hạng mục PMR, PAS và IMM - Hệ thống điện nhẹ | I20: A | J20: =MAX(0, IF(ISBLANK($W20), _xlfn.DAYS($J$1,$U20), _xlfn.DAYS($W20,$U20))) -> 10 | K20: =IF(($J20-21)>0,$J20-21,0) -> 0 | M20: Link | N20: Link | O20: Link | P20: Link | Q20: Link | R20: A | S20: 45457 | T20: 45457 | U20: 45457 | V20: 45463 | W20: 45467 | X20: Mr Phong + Shimada | Y20: 45469 | Z20: 45470 | AA20: =IF(AND($R20="",$I20=""),"",IF(OR($R20="B",$R20="C"),IF($Z20<>"",$Z20+7,IF($Y20<>"",$Y20+8,"")),IF($R20="",IF(OR($I20="B",$I20="C"),IF($W20<>"",$W20+7,IF($V20<>"",$V20+8,""))),""))) | AC20: =IF(OR($R20="B",$R20="C"),IF($AA20="","",IF($AB20="",IF($AA20>=$J$1,"In progress","Not submit yet"),IF($AA20>=$AB20,"Timely Response","Late Resubmission"))),"") | AD20: =IF(AC20="Late Resubmission",IF(AB20="","",AB20-AA20),IF(AC20="Not submit yet",IF(AA20="","",$J$1-AA20),"")) | AG20: =IF(AND(RIGHT($E20,1)>="A",RIGHT($E20,1)<="Z"),LEFT($E20,LEN($E20)-1),$E20) -> LTIA-5.10-VIETUR-70000-RFA-MAS-0271 | AH20: {=$E20=_xlfn.XLOOKUP( AG20, _xlfn._xlws.FILTER($AG$7:$AG$4572,$L$7:$L$4572<>"X"), _xlfn._xlws.FILTER($E$7:$E$4572,$L$7:$L$4572<>"X"), "", 0, -1 )} -> TRUE | AI20: =IF($AH20,IF(OR($R20="B",$R20="C"),"YES",IF($R20="",IF(OR($I20="B",$I20="C"),"YES",""),"")),"")
A21: =A20+1 -> 15 | B21: =MID(E21, FIND("-", E21) + 1, 4) -> 5.10 | C21: ACS | D21: MAS | E21: LTIA-5.10-VIETUR-70000-RFA-MAS-0305 | F21: =IF($U21=0,$T21+22,$U21+21) -> 45492 | G21: Request for approval Materials of Access Control System (ACS) | H21: Đề nghị phê duyệt vật tư hệ thống kiểm soát cửa ra vào | I21: C | J21: =MAX(0, IF(ISBLANK($W21), _xlfn.DAYS($J$1,$U21), _xlfn.DAYS($W21,$U21))) -> 33 | K21: =IF(($J21-21)>0,$J21-21,0) -> 12 | M21: Link | N21: Link | O21: Link | P21: Link | Q21: Link | R21: C | S21: 45471 | T21: 45471 | U21: 45471 | V21: 45484 | W21: 45504 | X21: Mr Phong + Shimada + Kuroda | Y21: 45524 | Z21: 45525 | AA21: =IF(AND($R21="",$I21=""),"",IF(OR($R21="B",$R21="C"),IF($Z21<>"",$Z21+7,IF($Y21<>"",$Y21+8,"")),IF($R21="",IF(OR($I21="B",$I21="C"),IF($W21<>"",$W21+7,IF($V21<>"",$V21+8,""))),""))) -> 45532 | AB21: 45562 | AC21: =IF(OR($R21="B",$R21="C"),IF($AA21="","",IF($AB21="",IF($AA21>=$J$1,"In progress","Not submit yet"),IF($AA21>=$AB21,"Timely Response","Late Resubmission"))),"") -> Late Resubmission | AD21: =IF(AC21="Late Resubmission",IF(AB21="","",AB21-AA21),IF(AC21="Not submit yet",IF(AA21="","",$J$1-AA21),"")) -> 30 | AG21: =IF(AND(RIGHT($E21,1)>="A",RIGHT($E21,1)<="Z"),LEFT($E21,LEN($E21)-1),$E21) -> LTIA-5.10-VIETUR-70000-RFA-MAS-0305 | AH21: {=$E21=_xlfn.XLOOKUP( AG21, _xlfn._xlws.FILTER($AG$7:$AG$4572,$L$7:$L$4572<>"X"), _xlfn._xlws.FILTER($E$7:$E$4572,$L$7:$L$4572<>"X"), "", 0, -1 )} -> FALSE | AI21: =IF($AH21,IF(OR($R21="B",$R21="C"),"YES",IF($R21="",IF(OR($I21="B",$I21="C"),"YES",""),"")),"")
A22: =A21+1 -> 16 | B22: =MID(E22, FIND("-", E22) + 1, 4) -> 5.10 | C22: PAS | D22: MAS | E22: LTIA-5.10-VIETUR-70000-RFA-MAS-0307 | F22: =IF($U22=0,$T22+22,$U22+21) -> 45497 | G22: Request for approval of equipment and all mounting accessories for Public address system (PAS) | H22: Yêu cầu phê duyệt thiết bị và tất cả các phụ kiện lắp đặt cho hệ thống âm thanh công cộng (PAS) | I22: C | J22: =MAX(0, IF(ISBLANK($W22), _xlfn.DAYS($J$1,$U22), _xlfn.DAYS($W22,$U22))) -> 22 | K22: =IF(($J22-21)>0,$J22-21,0) -> 1 | M22: Link | N22: Link | O22: Link | P22: Link | Q22: Link | R22: C | S22: 45476 | T22: 45476 | U22: 45476 | V22: 45491 | W22: 45498 | X22: Mr Phong + Kuroda | Y22: 45506 | Z22: 45511 | AA22: =IF(AND($R22="",$I22=""),"",IF(OR($R22="B",$R22="C"),IF($Z22<>"",$Z22+7,IF($Y22<>"",$Y22+8,"")),IF($R22="",IF(OR($I22="B",$I22="C"),IF($W22<>"",$W22+7,IF($V22<>"",$V22+8,""))),""))) -> 45518 | AB22: 45595 | AC22: =IF(OR($R22="B",$R22="C"),IF($AA22="","",IF($AB22="",IF($AA22>=$J$1,"In progress","Not submit yet"),IF($AA22>=$AB22,"Timely Response","Late Resubmission"))),"") -> Late Resubmission | AD22: =IF(AC22="Late Resubmission",IF(AB22="","",AB22-AA22),IF(AC22="Not submit yet",IF(AA22="","",$J$1-AA22),"")) -> 77 | AG22: =IF(AND(RIGHT($E22,1)>="A",RIGHT($E22,1)<="Z"),LEFT($E22,LEN($E22)-1),$E22) -> LTIA-5.10-VIETUR-70000-RFA-MAS-0307 | AH22: {=$E22=_xlfn.XLOOKUP( AG22, _xlfn._xlws.FILTER($AG$7:$AG$4572,$L$7:$L$4572<>"X"), _xlfn._xlws.FILTER($E$7:$E$4572,$L$7:$L$4572<>"X"), "", 0, -1 )} -> FALSE | AI22: =IF($AH22,IF(OR($R22="B",$R22="C"),"YES",IF($R22="",IF(OR($I22="B",$I22="C"),"YES",""),"")),"")
A23: =A22+1 -> 17 | B23: =MID(E23, FIND("-", E23) + 1, 4) -> 5.10 | C23: FAS | D23: MAS | E23: LTIA-5.10-VIETUR-72160-RFA-MSS-0082A | F23: =IF($U23=0,$T23+22,$U23+21) -> 45516 | G23: Request for approval for method statement of fire alarm system installation | H23: Đề nghị phê duyệt thuyết minh biện pháp thi công hệ thống báo cháy | I23: A | J23: =MAX(0, IF(ISBLANK($W23), _xlfn.DAYS($J$1,$U23), _xlfn.DAYS($W23,$U23))) -> 22 | K23: =IF(($J23-21)>0,$J23-21,0) -> 1 | M23: Link | N23: Link | O23: Link | P23: Link | Q23: Link | R23: A | S23: 45492 | T23: 45492 | U23: 45495 | V23: 45506 | W23: 45517 | X23: Mr Phong + Shimada | Y23: 45524 | Z23: 45492 | AA23: =IF(AND($R23="",$I23=""),"",IF(OR($R23="B",$R23="C"),IF($Z23<>"",$Z23+7,IF($Y23<>"",$Y23+8,"")),IF($R23="",IF(OR($I23="B",$I23="C"),IF($W23<>"",$W23+7,IF($V23<>"",$V23+8,""))),""))) | AC23: =IF(OR($R23="B",$R23="C"),IF($AA23="","",IF($AB23="",IF($AA23>=$J$1,"In progress","Not submit yet"),IF($AA23>=$AB23,"Timely Response","Late Resubmission"))),"") | AD23: =IF(AC23="Late Resubmission",IF(AB23="","",AB23-AA23),IF(AC23="Not submit yet",IF(AA23="","",$J$1-AA23),"")) | AG23: =IF(AND(RIGHT($E23,1)>="A",RIGHT($E23,1)<="Z"),LEFT($E23,LEN($E23)-1),$E23) -> LTIA-5.10-VIETUR-72160-RFA-MSS-0082 | AH23: {=$E23=_xlfn.XLOOKUP( AG23, _xlfn._xlws.FILTER($AG$7:$AG$4572,$L$7:$L$4572<>"X"), _xlfn._xlws.FILTER($E$7:$E$4572,$L$7:$L$4572<>"X"), "", 0, -1 )} -> TRUE | AI23: =IF($AH23,IF(OR($R23="B",$R23="C"),"YES",IF($R23="",IF(OR($I23="B",$I23="C"),"YES",""),"")),"")
A24: =A23+1 -> 18 | B24: =MID(E24, FIND("-", E24) + 1, 4) -> 5.10 | C24: FAS | D24: MAS | E24: LTIA-5.10-VIETUR-70000-RFA-MAS-0318 | F24: =IF($U24=0,$T24+22,$U24+21) -> 45518 | G24: Request for approval material cable fire resistant shield for fire alarm system (Norden) | H24: Đề nghị phê duyệt vật liệu cáp chống cháy cho hệ thống báo cháy (Norden) | I24: A | J24: =MAX(0, IF(ISBLANK($W24), _xlfn.DAYS($J$1,$U24), _xlfn.DAYS($W24,$U24))) -> 7 | K24: =IF(($J24-21)>0,$J24-21,0) -> 0 | L24: X | M24: Link | N24: Link | O24: Link | P24: Link | Q24: Link | R24: A | S24: 45496 | T24: 45496 | U24: 45497 | V24: 45503 | W24: 45504 | X24: Mr Phong + Shimada + Kuroda | Y24: 45516 | Z24: 45517 | AA24: =IF(AND($R24="",$I24=""),"",IF(OR($R24="B",$R24="C"),IF($Z24<>"",$Z24+7,IF($Y24<>"",$Y24+8,"")),IF($R24="",IF(OR($I24="B",$I24="C"),IF($W24<>"",$W24+7,IF($V24<>"",$V24+8,""))),""))) | AC24: =IF(OR($R24="B",$R24="C"),IF($AA24="","",IF($AB24="",IF($AA24>=$J$1,"In progress","Not submit yet"),IF($AA24>=$AB24,"Timely Response","Late Resubmission"))),"") | AD24: =IF(AC24="Late Resubmission",IF(AB24="","",AB24-AA24),IF(AC24="Not submit yet",IF(AA24="","",$J$1-AA24),"")) | AE24: 1/2/2025 Update => 0318A | AG24: =IF(AND(RIGHT($E24,1)>="A",RIGHT($E24,1)<="Z"),LEFT($E24,LEN($E24)-1),$E24) -> LTIA-5.10-VIETUR-70000-RFA-MAS-0318 | AH24: {=$E24=_xlfn.XLOOKUP( AG24, _xlfn._xlws.FILTER($AG$7:$AG$4572,$L$7:$L$4572<>"X"), _xlfn._xlws.FILTER($E$7:$E$4572,$L$7:$L$4572<>"X"), "", 0, -1 )} -> FALSE | AI24: =IF($AH24,IF(OR($R24="B",$R24="C"),"YES",IF($R24="",IF(OR($I24="B",$I24="C"),"YES",""),"")),"")
A25: =A24+1 -> 19 | B25: =MID(E25, FIND("-", E25) + 1, 4) -> 5.10 | C25: FAS | D25: MAS | E25: LTIA-5.10-VIETUR-70000-RFA-MAS-0320 | F25: =IF($U25=0,$T25+22,$U25+21) -> 45518 | G25: Request for approval for accessories of GI conduit and equipment mounting (Cat Van Loi) for fire alarm system | H25: Đề nghị phê duyệt vật tư về phụ kiện ống thép GI luồn dây và giá treo thiết bị (Cát Vạn Lợi) cho hệ thống báo cháy | I25: A | J25: =MAX(0, IF(ISBLANK($W25), _xlfn.DAYS($J$1,$U25), _xlfn.DAYS($W25,$U25))) -> 12 | K25: =IF(($J25-21)>0,$J25-21,0) -> 0 | M25: Link | N25: Link | O25: Link | P25: Link | Q25: Link | R25: A | S25: 45496 | T25: 45496 | U25: 45497 | V25: 45504 | W25: 45509 | X25: Mr Phong + Shimada | Y25: 45519 | Z25: 45520 | AA25: =IF(AND($R25="",$I25=""),"",IF(OR($R25="B",$R25="C"),IF($Z25<>"",$Z25+7,IF($Y25<>"",$Y25+8,"")),IF($R25="",IF(OR($I25="B",$I25="C"),IF($W25<>"",$W25+7,IF($V25<>"",$V25+8,""))),""))) | AC25: =IF(OR($R25="B",$R25="C"),IF($AA25="","",IF($AB25="",IF($AA25>=$J$1,"In progress","Not submit yet"),IF($AA25>=$AB25,"Timely Response","Late Resubmission"))),"") | AD25: =IF(AC25="Late Resubmission",IF(AB25="","",AB25-AA25),IF(AC25="Not submit yet",IF(AA25="","",$J$1-AA25),"")) | AG25: =IF(AND(RIGHT($E25,1)>="A",RIGHT($E25,1)<="Z"),LEFT($E25,LEN($E25)-1),$E25) -> LTIA-5.10-VIETUR-70000-RFA-MAS-0320 | AH25: {=$E25=_xlfn.XLOOKUP( AG25, _xlfn._xlws.FILTER($AG$7:$AG$4572,$L$7:$L$4572<>"X"), _xlfn._xlws.FILTER($E$7:$E$4572,$L$7:$L$4572<>"X"), "", 0, -1 )} -> TRUE | AI25: =IF($AH25,IF(OR($R25="B",$R25="C"),"YES",IF($R25="",IF(OR($I25="B",$I25="C"),"YES",""),"")),"")
A26: =A25+1 -> 20 | B26: =MID(E26, FIND("-", E26) + 1, 4) -> 5.10 | C26: FAS | D26: MAS | E26: LTIA-5.10-VIETUR-70000-RFA-MAS-0208A | F26: =IF($U26=0,$T26+22,$U26+21) -> 45533 | G26: Request for approval of fire alarm equipment for fire alarm system | H26: Đề nghị phê duyệt thiết bị báo cháy cho hệ thống báo cháy | I26: A | J26: =MAX(0, IF(ISBLANK($W26), _xlfn.DAYS($J$1,$U26), _xlfn.DAYS($W26,$U26))) -> 18 | K26: =IF(($J26-21)>0,$J26-21,0) -> 0 | M26: Link | N26: Link | O26: Link | P26: Link | Q26: Link | R26: A | S26: 45512 | T26: 45512 | U26: 45512 | V26: 45530 | W26: 45530 | X26: Mr Phong + Shimada | Y26: 45545 | Z26: 45546 | AA26: =IF(AND($R26="",$I26=""),"",IF(OR($R26="B",$R26="C"),IF($Z26<>"",$Z26+7,IF($Y26<>"",$Y26+8,"")),IF($R26="",IF(OR($I26="B",$I26="C"),IF($W26<>"",$W26+7,IF($V26<>"",$V26+8,""))),""))) | AC26: =IF(OR($R26="B",$R26="C"),IF($AA26="","",IF($AB26="",IF($AA26>=$J$1,"In progress","Not submit yet"),IF($AA26>=$AB26,"Timely Response","Late Resubmission"))),"") | AD26: =IF(AC26="Late Resubmission",IF(AB26="","",AB26-AA26),IF(AC26="Not submit yet",IF(AA26="","",$J$1-AA26),"")) | AG26: =IF(AND(RIGHT($E26,1)>="A",RIGHT($E26,1)<="Z"),LEFT($E26,LEN($E26)-1),$E26) -> LTIA-5.10-VIETUR-70000-RFA-MAS-0208 | AH26: {=$E26=_xlfn.XLOOKUP( AG26, _xlfn._xlws.FILTER($AG$7:$AG$4572,$L$7:$L$4572<>"X"), _xlfn._xlws.FILTER($E$7:$E$4572,$L$7:$L$4572<>"X"), "", 0, -1 )} -> TRUE | AI26: =IF($AH26,IF(OR($R26="B",$R26="C"),"YES",IF($R26="",IF(OR($I26="B",$I26="C"),"YES",""),"")),"")
A27: =A26+1 -> 21 | B27: =MID(E27, FIND("-", E27) + 1, 4) -> 5.10 | C27: MCS | D27: MSS | E27: LTIA-5.10-VIETUR-70000-RFA-MSS-0123 | F27: =IF($U27=0,$T27+22,$U27+21) -> 45540 | G27: Request for approval of installation methods master clock system | H27: Đề nghị phê duyệt biện pháp thi công lắp đặt hệ thống đồng hồ chủ | I27: B | J27: =MAX(0, IF(ISBLANK($W27), _xlfn.DAYS($J$1,$U27), _xlfn.DAYS($W27,$U27))) -> 15 | K27: =IF(($J27-21)>0,$J27-21,0) -> 0 | M27: Link | N27: Link | O27: Link | P27: Link | Q27: Link | R27: B | S27: 45518 | T27: 45518 | U27: 45519 | V27: 45533 | W27: 45534 | X27: Mr Cường + Shimada | Y27: 45548 | Z27: 45548 | AA27: =IF(AND($R27="",$I27=""),"",IF(OR($R27="B",$R27="C"),IF($Z27<>"",$Z27+7,IF($Y27<>"",$Y27+8,"")),IF($R27="",IF(OR($I27="B",$I27="C"),IF($W27<>"",$W27+7,IF($V27<>"",$V27+8,""))),""))) -> 45555 | AB27: 45581 | AC27: =IF(OR($R27="B",$R27="C"),IF($AA27="","",IF($AB27="",IF($AA27>=$J$1,"In progress","Not submit yet"),IF($AA27>=$AB27,"Timely Response","Late Resubmission"))),"") -> Late Resubmission | AD27: =IF(AC27="Late Resubmission",IF(AB27="","",AB27-AA27),IF(AC27="Not submit yet",IF(AA27="","",$J$1-AA27),"")) -> 26 | AG27: =IF(AND(RIGHT($E27,1)>="A",RIGHT($E27,1)<="Z"),LEFT($E27,LEN($E27)-1),$E27) -> LTIA-5.10-VIETUR-70000-RFA-MSS-0123 | AH27: {=$E27=_xlfn.XLOOKUP( AG27, _xlfn._xlws.FILTER($AG$7:$AG$4572,$L$7:$L$4572<>"X"), _xlfn._xlws.FILTER($E$7:$E$4572,$L$7:$L$4572<>"X"), "", 0, -1 )} -> FALSE | AI27: =IF($AH27,IF(OR($R27="B",$R27="C"),"YES",IF($R27="",IF(OR($I27="B",$I27="C"),"YES",""),"")),"")
A28: =A27+1 -> 22 | B28: =MID(E28, FIND("-", E28) + 1, 4) -> 5.10 | C28: SCS | D28: MAS | E28: LTIA-5.10-VIETUR-70000-RFA-MAS-0158A | F28: =IF($U28=0,$T28+22,$U28+21) -> 45546 | G28: Request for approval of ICT cable - ELV system | H28: Đề nghị phê duyệt vật tư cáp điện nhẹ - Hệ thống điện nhẹ | I28: C | J28: =MAX(0, IF(ISBLANK($W28), _xlfn.DAYS($J$1,$U28), _xlfn.DAYS($W28,$U28))) -> 58 | K28: =IF(($J28-21)>0,$J28-21,0) -> 37 | M28: Link | N28: Link | O28: Link | P28: Link | Q28: Link | R28: C | S28: 45525 | T28: 45525 | U28: 45525 | V28: 45539 | W28: 45583 | X28: Mr Phong + Shimada | Y28: 45588 | Z28: 45590 | AA28: =IF(AND($R28="",$I28=""),"",IF(OR($R28="B",$R28="C"),IF($Z28<>"",$Z28+7,IF($Y28<>"",$Y28+8,"")),IF($R28="",IF(OR($I28="B",$I28="C"),IF($W28<>"",$W28+7,IF($V28<>"",$V28+8,""))),""))) -> 45597 | AB28: 45603 | AC28: =IF(OR($R28="B",$R28="C"),IF($AA28="","",IF($AB28="",IF($AA28>=$J$1,"In progress","Not submit yet"),IF($AA28>=$AB28,"Timely Response","Late Resubmission"))),"") -> Late Resubmission | AD28: =IF(AC28="Late Resubmission",IF(AB28="","",AB28-AA28),IF(AC28="Not submit yet",IF(AA28="","",$J$1-AA28),"")) -> 6 | AG28: =IF(AND(RIGHT($E28,1)>="A",RIGHT($E28,1)<="Z"),LEFT($E28,LEN($E28)-1),$E28) -> LTIA-5.10-VIETUR-70000-RFA-MAS-0158 | AH28: {=$E28=_xlfn.XLOOKUP( AG28, _xlfn._xlws.FILTER($AG$7:$AG$4572,$L$7:$L$4572<>"X"), _xlfn._xlws.FILTER($E$7:$E$4572,$L$7:$L$4572<>"X"), "", 0, -1 )} -> FALSE | AI28: =IF($AH28,IF(OR($R28="B",$R28="C"),"YES",IF($R28="",IF(OR($I28="B",$I28="C"),"YES",""),"")),"")
A29: =A28+1 -> 23 | B29: =MID(E29, FIND("-", E29) + 1, 4) -> 5.10 | C29: PAS | D29: MAS | E29: LTIA-5.10-VIETUR-70000-RFA-MAS-0307A | F29: =IF($U29=0,$T29+22,$U29+21) -> 45616 | G29: Request for approval of equipment and all mounting accessories for Public address system (PAS) | H29: Yêu cầu phê duyệt thiết bị và tất cả các phụ kiện lắp đặt cho hệ thống âm thanh công cộng (PAS) | I29: A | J29: =MAX(0, IF(ISBLANK($W29), _xlfn.DAYS($J$1,$U29), _xlfn.DAYS($W29,$U29))) -> 21 | K29: =IF(($J29-21)>0,$J29-21,0) -> 0 | M29: Link | N29: Link | O29: Link | P29: Link | Q29: Link | R29: A | S29: 45595 | T29: 45595 | U29: 45595 | V29: 45609 | W29: 45616 | X29: Mr Phong + Shimada | Y29: 45985 | Z29: 45621 | AA29: =IF(AND($R29="",$I29=""),"",IF(OR($R29="B",$R29="C"),IF($Z29<>"",$Z29+7,IF($Y29<>"",$Y29+8,"")),IF($R29="",IF(OR($I29="B",$I29="C"),IF($W29<>"",$W29+7,IF($V29<>"",$V29+8,""))),""))) | AC29: =IF(OR($R29="B",$R29="C"),IF($AA29="","",IF($AB29="",IF($AA29>=$J$1,"In progress","Not submit yet"),IF($AA29>=$AB29,"Timely Response","Late Resubmission"))),"") | AD29: =IF(AC29="Late Resubmission",IF(AB29="","",AB29-AA29),IF(AC29="Not submit yet",IF(AA29="","",$J$1-AA29),"")) | AG29: =IF(AND(RIGHT($E29,1)>="A",RIGHT($E29,1)<="Z"),LEFT($E29,LEN($E29)-1),$E29) -> LTIA-5.10-VIETUR-70000-RFA-MAS-0307 | AH29: {=$E29=_xlfn.XLOOKUP( AG29, _xlfn._xlws.FILTER($AG$7:$AG$4572,$L$7:$L$4572<>"X"), _xlfn._xlws.FILTER($E$7:$E$4572,$L$7:$L$4572<>"X"), "", 0, -1 )} -> TRUE | AI29: =IF($AH29,IF(OR($R29="B",$R29="C"),"YES",IF($R29="",IF(OR($I29="B",$I29="C"),"YES",""),"")),"")
A30: =A29+1 -> 24 | B30: =MID(E30, FIND("-", E30) + 1, 4) -> 5.10 | C30: SCS | D30: MAS | E30: LTIA-5.10-VIETUR-70000-RFA-MAS-0258A | F30: =IF($U30=0,$T30+22,$U30+21) -> 45575 | G30: Request for approval Material of structured cabling system (SCS) | H30: Đề nghị phê duyệt vật tư hệ thống cấu trúc mạng | I30: C | J30: =MAX(0, IF(ISBLANK($W30), _xlfn.DAYS($J$1,$U30), _xlfn.DAYS($W30,$U30))) -> 50 | K30: =IF(($J30-21)>0,$J30-21,0) -> 29 | M30: Link | N30: Link | O30: Link | P30: Link | Q30: Link | R30: C | S30: 45553 | T30: 45553 | U30: 45554 | V30: 45567 | W30: 45604 | X30: Mr Phong + Shimada | Y30: 45617 | Z30: 45617 | AA30: =IF(AND($R30="",$I30=""),"",IF(OR($R30="B",$R30="C"),IF($Z30<>"",$Z30+7,IF($Y30<>"",$Y30+8,"")),IF($R30="",IF(OR($I30="B",$I30="C"),IF($W30<>"",$W30+7,IF($V30<>"",$V30+8,""))),""))) -> 45624 | AB30: 45719 | AC30: =IF(OR($R30="B",$R30="C"),IF($AA30="","",IF($AB30="",IF($AA30>=$J$1,"In progress","Not submit yet"),IF($AA30>=$AB30,"Timely Response","Late Resubmission"))),"") -> Late Resubmission | AD30: =IF(AC30="Late Resubmission",IF(AB30="","",AB30-AA30),IF(AC30="Not submit yet",IF(AA30="","",$J$1-AA30),"")) -> 95 | AG30: =IF(AND(RIGHT($E30,1)>="A",RIGHT($E30,1)<="Z"),LEFT($E30,LEN($E30)-1),$E30) -> LTIA-5.10-VIETUR-70000-RFA-MAS-0258 | AH30: {=$E30=_xlfn.XLOOKUP( AG30, _xlfn._xlws.FILTER($AG$7:$AG$4572,$L$7:$L$4572<>"X"), _xlfn._xlws.FILTER($E$7:$E$4572,$L$7:$L$4572<>"X"), "", 0, -1 )} -> FALSE | AI30: =IF($AH30,IF(OR($R30="B",$R30="C"),"YES",IF($R30="",IF(OR($I30="B",$I30="C"),"YES",""),"")),"")
A31: =A30+1 -> 25 | B31: =MID(E31, FIND("-", E31) + 1, 4) -> 5.10 | C31: ACS | D31: MAS | E31: LTIA-5.10-VIETUR-70000-RFA-MAS-0305A | F31: =IF($U31=0,$T31+22,$U31+21) -> 45586 | G31: Request for approval Materials of Access Control System (ACS) | H31: Đề nghị phê duyệt vật tư hệ thống kiểm soát cửa ra vào | I31: B | J31: =MAX(0, IF(ISBLANK($W31), _xlfn.DAYS($J$1,$U31), _xlfn.DAYS($W31,$U31))) -> 29 | K31: =IF(($J31-21)>0,$J31-21,0) -> 8 | M31: Link | N31: Link | O31: Link | P31: Link | Q31: Link | R31: B | S31: 45562 | T31: 45562 | U31: 45565 | V31: 45576 | W31: 45594 | X31: Mr Cường + Shimada | Y31: 45609 | Z31: 45609 | AA31: =IF(AND($R31="",$I31=""),"",IF(OR($R31="B",$R31="C"),IF($Z31<>"",$Z31+7,IF($Y31<>"",$Y31+8,"")),IF($R31="",IF(OR($I31="B",$I31="C"),IF($W31<>"",$W31+7,IF($V31<>"",$V31+8,""))),""))) -> 45616 | AB31: 45630 | AC31: =IF(OR($R31="B",$R31="C"),IF($AA31="","",IF($AB31="",IF($AA31>=$J$1,"In progress","Not submit yet"),IF($AA31>=$AB31,"Timely Response","Late Resubmission"))),"") -> Late Resubmission | AD31: =IF(AC31="Late Resubmission",IF(AB31="","",AB31-AA31),IF(AC31="Not submit yet",IF(AA31="","",$J$1-AA31),"")) -> 14 | AG31: =IF(AND(RIGHT($E31,1)>="A",RIGHT($E31,1)<="Z"),LEFT($E31,LEN($E31)-1),$E31) -> LTIA-5.10-VIETUR-70000-RFA-MAS-0305 | AH31: {=$E31=_xlfn.XLOOKUP( AG31, _xlfn._xlws.FILTER($AG$7:$AG$4572,$L$7:$L$4572<>"X"), _xlfn._xlws.FILTER($E$7:$E$4572,$L$7:$L$4572<>"X"), "", 0, -1 )} -> FALSE | AI31: =IF($AH31,IF(OR($R31="B",$R31="C"),"YES",IF($R31="",IF(OR($I31="B",$I31="C"),"YES",""),"")),"")
A32: =A31+1 -> 26 | B32: =MID(E32, FIND("-", E32) + 1, 4) -> 5.10 | C32: MCS | D32: MSS | E32: LTIA-5.10-VIETUR-70000-RFA-MSS-0123A | F32: =IF($U32=0,$T32+22,$U32+21) -> 45602 | G32: Request for approval of installation methods master clock system | H32: Đề nghị phê duyệt biện pháp thi công lắp đặt hệ thống đồng hồ chủ | I32: A | J32: =MAX(0, IF(ISBLANK($W32), _xlfn.DAYS($J$1,$U32), _xlfn.DAYS($W32,$U32))) -> 9 | K32: =IF(($J32-21)>0,$J32-21,0) -> 0 | M32: Link | N32: Link | O32: Link | P32: Link | Q32: Link | R32: A | S32: 45581 | T32: 45581 | U32: 45581 | V32: 45589 | W32: 45590 | X32: Mr Cường + Shimada | Y32: 45594 | Z32: 45595 | AA32: =IF(AND($R32="",$I32=""),"",IF(OR($R32="B",$R32="C"),IF($Z32<>"",$Z32+7,IF($Y32<>"",$Y32+8,"")),IF($R32="",IF(OR($I32="B",$I32="C"),IF($W32<>"",$W32+7,IF($V32<>"",$V32+8,""))),""))) | AC32: =IF(OR($R32="B",$R32="C"),IF($AA32="","",IF($AB32="",IF($AA32>=$J$1,"In progress","Not submit yet"),IF($AA32>=$AB32,"Timely Response","Late Resubmission"))),"") | AD32: =IF(AC32="Late Resubmission",IF(AB32="","",AB32-AA32),IF(AC32="Not submit yet",IF(AA32="","",$J$1-AA32),"")) | AG32: =IF(AND(RIGHT($E32,1)>="A",RIGHT($E32,1)<="Z"),LEFT($E32,LEN($E32)-1),$E32) -> LTIA-5.10-VIETUR-70000-RFA-MSS-0123 | AH32: {=$E32=_xlfn.XLOOKUP( AG32, _xlfn._xlws.FILTER($AG$7:$AG$4572,$L$7:$L$4572<>"X"), _xlfn._xlws.FILTER($E$7:$E$4572,$L$7:$L$4572<>"X"), "", 0, -1 )} -> TRUE | AI32: =IF($AH32,IF(OR($R32="B",$R32="C"),"YES",IF($R32="",IF(OR($I32="B",$I32="C"),"YES",""),"")),"")
A33: =A32+1 -> 27 | B33: =MID(E33, FIND("-", E33) + 1, 4) -> 5.10 | C33: SCS | D33: MAS | E33: LTIA-5.10-VIETUR-70000-RFA-MAS-0158B | F33: =IF($U33=0,$T33+22,$U33+21) -> 45624 | G33: Request for approval of ICT cable - ELV system | H33: Đề nghị phê duyệt vật tư cáp điện nhẹ - Hệ thống điện nhẹ | I33: C | J33: =MAX(0, IF(ISBLANK($W33), _xlfn.DAYS($J$1,$U33), _xlfn.DAYS($W33,$U33))) -> 35 | K33: =IF(($J33-21)>0,$J33-21,0) -> 14 | M33: Link | N33: Link | O33: Link | P33: Link | Q33: Link | R33: C | S33: 45603 | T33: 45603 | U33: 45603 | V33: 45618 | W33: 45638 | X33: Mr Hiếu + Kuroda | Y33: 45652 | Z33: 45656 | AA33: =IF(AND($R33="",$I33=""),"",IF(OR($R33="B",$R33="C"),IF($Z33<>"",$Z33+7,IF($Y33<>"",$Y33+8,"")),IF($R33="",IF(OR($I33="B",$I33="C"),IF($W33<>"",$W33+7,IF($V33<>"",$V33+8,""))),""))) -> 45663 | AB33: 45666 | AC33: =IF(OR($R33="B",$R33="C"),IF($AA33="","",IF($AB33="",IF($AA33>=$J$1,"In progress","Not submit yet"),IF($AA33>=$AB33,"Timely Response","Late Resubmission"))),"") -> Late Resubmission | AD33: =IF(AC33="Late Resubmission",IF(AB33="","",AB33-AA33),IF(AC33="Not submit yet",IF(AA33="","",$J$1-AA33),"")) -> 3 | AG33: =IF(AND(RIGHT($E33,1)>="A",RIGHT($E33,1)<="Z"),LEFT($E33,LEN($E33)-1),$E33) -> LTIA-5.10-VIETUR-70000-RFA-MAS-0158 | AH33: {=$E33=_xlfn.XLOOKUP( AG33, _xlfn._xlws.FILTER($AG$7:$AG$4572,$L$7:$L$4572<>"X"), _xlfn._xlws.FILTER($E$7:$E$4572,$L$7:$L$4572<>"X"), "", 0, -1 )} -> FALSE | AI33: =IF($AH33,IF(OR($R33="B",$R33="C"),"YES",IF($R33="",IF(OR($I33="B",$I33="C"),"YES",""),"")),"")
A34: =A33+1 -> 28 | B34: =MID(E34, FIND("-", E34) + 1, 4) -> 5.10 | C34: SCS PMR | D34: MAS | E34: LTIA-5.10-VIETUR-70000-RFA-MAS-0409 | F34: =IF($U34=0,$T34+22,$U34+21) -> 45635 | G34: Request for approval of additional ICT cable of Item PMR - ELV system | H34: Đề nghị phê duyệt bổ sung vật tư cáp điện nhẹ của hạng mục PMR - Hệ thống điện nhẹ | I34: A | J34: =MAX(0, IF(ISBLANK($W34), _xlfn.DAYS($J$1,$U34), _xlfn.DAYS($W34,$U34))) -> 14 | K34: =IF(($J34-21)>0,$J34-21,0) -> 0 | M34: Link | N34: Link | O34: Link | P34: Link | Q34: Link | R34: A | S34: 45614 | T34: 45614 | U34: 45614 | V34: 45628 | W34: 45628 | X34: Mr Phong + Shimada | Y34: 45646 | Z34: 45649 | AA34: =IF(AND($R34="",$I34=""),"",IF(OR($R34="B",$R34="C"),IF($Z34<>"",$Z34+7,IF($Y34<>"",$Y34+8,"")),IF($R34="",IF(OR($I34="B",$I34="C"),IF($W34<>"",$W34+7,IF($V34<>"",$V34+8,""))),""))) | AC34: =IF(OR($R34="B",$R34="C"),IF($AA34="","",IF($AB34="",IF($AA34>=$J$1,"In progress","Not submit yet"),IF($AA34>=$AB34,"Timely Response","Late Resubmission"))),"") | AD34: =IF(AC34="Late Resubmission",IF(AB34="","",AB34-AA34),IF(AC34="Not submit yet",IF(AA34="","",$J$1-AA34),"")) | AG34: =IF(AND(RIGHT($E34,1)>="A",RIGHT($E34,1)<="Z"),LEFT($E34,LEN($E34)-1),$E34) -> LTIA-5.10-VIETUR-70000-RFA-MAS-0409 | AH34: {=$E34=_xlfn.XLOOKUP( AG34, _xlfn._xlws.FILTER($AG$7:$AG$4572,$L$7:$L$4572<>"X"), _xlfn._xlws.FILTER($E$7:$E$4572,$L$7:$L$4572<>"X"), "", 0, -1 )} -> TRUE | AI34: =IF($AH34,IF(OR($R34="B",$R34="C"),"YES",IF($R34="",IF(OR($I34="B",$I34="C"),"YES",""),"")),"")
A35: =A34+1 -> 29 | B35: =MID(E35, FIND("-", E35) + 1, 4) -> 5.10 | C35: ACS | D35: MAS | E35: LTIA-5.10-VIETUR-70000-RFA-MAS-0305B | F35: =IF($U35=0,$T35+22,$U35+21) -> 45651 | G35: Request for approval Materials of Access Control System (ACS) | H35: Đề nghị phê duyệt vật tư hệ thống kiểm soát cửa ra vào | I35: A | J35: =MAX(0, IF(ISBLANK($W35), _xlfn.DAYS($J$1,$U35), _xlfn.DAYS($W35,$U35))) -> 17 | K35: =IF(($J35-21)>0,$J35-21,0) -> 0 | M35: Link | N35: Link | O35: Link | P35: Link | Q35: Link | R35: A | S35: 45630 | T35: 45630 | U35: 45630 | V35: 45643 | W35: 45647 | X35: Mr Cường + Kuroda | Y35: 45665 | Z35: 45670 | AA35: =IF(AND($R35="",$I35=""),"",IF(OR($R35="B",$R35="C"),IF($Z35<>"",$Z35+7,IF($Y35<>"",$Y35+8,"")),IF($R35="",IF(OR($I35="B",$I35="C"),IF($W35<>"",$W35+7,IF($V35<>"",$V35+8,""))),""))) | AC35: =IF(OR($R35="B",$R35="C"),IF($AA35="","",IF($AB35="",IF($AA35>=$J$1,"In progress","Not submit yet"),IF($AA35>=$AB35,"Timely Response","Late Resubmission"))),"") | AD35: =IF(AC35="Late Resubmission",IF(AB35="","",AB35-AA35),IF(AC35="Not submit yet",IF(AA35="","",$J$1-AA35),"")) | AG35: =IF(AND(RIGHT($E35,1)>="A",RIGHT($E35,1)<="Z"),LEFT($E35,LEN($E35)-1),$E35) -> LTIA-5.10-VIETUR-70000-RFA-MAS-0305 | AH35: {=$E35=_xlfn.XLOOKUP( AG35, _xlfn._xlws.FILTER($AG$7:$AG$4572,$L$7:$L$4572<>"X"), _xlfn._xlws.FILTER($E$7:$E$4572,$L$7:$L$4572<>"X"), "", 0, -1 )} -> TRUE | AI35: =IF($AH35,IF(OR($R35="B",$R35="C"),"YES",IF($R35="",IF(OR($I35="B",$I35="C"),"YES",""),"")),"")
A36: =A35+1 -> 30 | B36: =MID(E36, FIND("-", E36) + 1, 4) -> 5.10 | C36: FAS | D36: MAS | E36: LTIA-5.10-VIETUR-70000-RFA-MAS-0318A | F36: =IF($U36=0,$T36+22,$U36+21) -> 45680 | G36: Request for approval material cable fire resistant shield for fire alarm system (Norden) | H36: Đề nghị phê duyệt vật liệu cáp chống cháy cho hệ thống báo cháy (Norden) | I36: A | J36: =MAX(0, IF(ISBLANK($W36), _xlfn.DAYS($J$1,$U36), _xlfn.DAYS($W36,$U36))) -> 7 | K36: =IF(($J36-21)>0,$J36-21,0) -> 0 | M36: Link | N36: Link | O36: Link | P36: Link | Q36: Link | R36: A | S36: 45659 | T36: 45659 | U36: 45659 | V36: 45665 | W36: 45666 | X36: Mr Phong + Shimada | Y36: 45695 | Z36: 45700 | AA36: =IF(AND($R36="",$I36=""),"",IF(OR($R36="B",$R36="C"),IF($Z36<>"",$Z36+7,IF($Y36<>"",$Y36+8,"")),IF($R36="",IF(OR($I36="B",$I36="C"),IF($W36<>"",$W36+7,IF($V36<>"",$V36+8,""))),""))) | AC36: =IF(OR($R36="B",$R36="C"),IF($AA36="","",IF($AB36="",IF($AA36>=$J$1,"In progress","Not submit yet"),IF($AA36>=$AB36,"Timely Response","Late Resubmission"))),"") | AD36: =IF(AC36="Late Resubmission",IF(AB36="","",AB36-AA36),IF(AC36="Not submit yet",IF(AA36="","",$J$1-AA36),"")) | AG36: =IF(AND(RIGHT($E36,1)>="A",RIGHT($E36,1)<="Z"),LEFT($E36,LEN($E36)-1),$E36) -> LTIA-5.10-VIETUR-70000-RFA-MAS-0318 | AH36: {=$E36=_xlfn.XLOOKUP( AG36, _xlfn._xlws.FILTER($AG$7:$AG$4572,$L$7:$L$4572<>"X"), _xlfn._xlws.FILTER($E$7:$E$4572,$L$7:$L$4572<>"X"), "", 0, -1 )} -> TRUE | AI36: =IF($AH36,IF(OR($R36="B",$R36="C"),"YES",IF($R36="",IF(OR($I36="B",$I36="C"),"YES",""),"")),"")
A37: =A36+1 -> 31 | B37: =MID(E37, FIND("-", E37) + 1, 4) -> 5.10 | C37: SCS | D37: OTH | E37: LTIA-5.10-VIETUR-70000-RFA-OTH-0328 | F37: =IF($U37=0,$T37+22,$U37+21) -> 45656 | G37: Report for site inspection on the installation for junction box and data outlet connection | H37: Báo cáo kiểm tra thực tế phương án lắp đặt hộp đấu nối và kết nối ổ cắm dữ liệu | I37: A | J37: =MAX(0, IF(ISBLANK($W37), _xlfn.DAYS($J$1,$U37), _xlfn.DAYS($W37,$U37))) -> 12 | K37: =IF(($J37-21)>0,$J37-21,0) -> 0 | M37: Link | N37: Link | O37: Link | P37: Link | Q37: Link | R37: A | S37: 45635 | T37: 45635 | U37: 45635 | V37: 45646 | W37: 45647 | X37: Mr Phong + Kuroda | Y37: 45659 | Z37: 45660 | AA37: =IF(AND($R37="",$I37=""),"",IF(OR($R37="B",$R37="C"),IF($Z37<>"",$Z37+7,IF($Y37<>"",$Y37+8,"")),IF($R37="",IF(OR($I37="B",$I37="C"),IF($W37<>"",$W37+7,IF($V37<>"",$V37+8,""))),""))) | AC37: =IF(OR($R37="B",$R37="C"),IF($AA37="","",IF($AB37="",IF($AA37>=$J$1,"In progress","Not submit yet"),IF($AA37>=$AB37,"Timely Response","Late Resubmission"))),"") | AD37: =IF(AC37="Late Resubmission",IF(AB37="","",AB37-AA37),IF(AC37="Not submit yet",IF(AA37="","",$J$1-AA37),"")) | AG37: =IF(AND(RIGHT($E37,1)>="A",RIGHT($E37,1)<="Z"),LEFT($E37,LEN($E37)-1),$E37) -> LTIA-5.10-VIETUR-70000-RFA-OTH-0328 | AH37: {=$E37=_xlfn.XLOOKUP( AG37, _xlfn._xlws.FILTER($AG$7:$AG$4572,$L$7:$L$4572<>"X"), _xlfn._xlws.FILTER($E$7:$E$4572,$L$7:$L$4572<>"X"), "", 0, -1 )} -> TRUE | AI37: =IF($AH37,IF(OR($R37="B",$R37="C"),"YES",IF($R37="",IF(OR($I37="B",$I37="C"),"YES",""),"")),"")
A38: =A37+1 -> 32 | B38: =MID(E38, FIND("-", E38) + 1, 4) -> 5.10 | C38: SCS | D38: MAS | E38: LTIA-5.10-VIETUR-70000-RFA-MAS-0158C | F38: =IF($U38=0,$T38+22,$U38+21) -> 45688 | G38: Request for approval of ICT cable - ELV system | H38: Đề nghị phê duyệt vật tư cáp điện nhẹ - Hệ thống điện nhẹ | I38: A | J38: =MAX(0, IF(ISBLANK($W38), _xlfn.DAYS($J$1,$U38), _xlfn.DAYS($W38,$U38))) -> 27 | K38: =IF(($J38-21)>0,$J38-21,0) -> 6 | M38: Link | N38: Link | O38: Link | P38: Link | Q38: Link | R38: A | S38: 45666 | T38: 45666 | U38: 45667 | V38: 45681 | W38: 45694 | X38: Mr Shimada + Kuroda | Y38: 45695 | Z38: 45700 | AA38: =IF(AND($R38="",$I38=""),"",IF(OR($R38="B",$R38="C"),IF($Z38<>"",$Z38+7,IF($Y38<>"",$Y38+8,"")),IF($R38="",IF(OR($I38="B",$I38="C"),IF($W38<>"",$W38+7,IF($V38<>"",$V38+8,""))),""))) | AC38: =IF(OR($R38="B",$R38="C"),IF($AA38="","",IF($AB38="",IF($AA38>=$J$1,"In progress","Not submit yet"),IF($AA38>=$AB38,"Timely Response","Late Resubmission"))),"") | AD38: =IF(AC38="Late Resubmission",IF(AB38="","",AB38-AA38),IF(AC38="Not submit yet",IF(AA38="","",$J$1-AA38),"")) | AG38: =IF(AND(RIGHT($E38,1)>="A",RIGHT($E38,1)<="Z"),LEFT($E38,LEN($E38)-1),$E38) -> LTIA-5.10-VIETUR-70000-RFA-MAS-0158 | AH38: {=$E38=_xlfn.XLOOKUP( AG38, _xlfn._xlws.FILTER($AG$7:$AG$4572,$L$7:$L$4572<>"X"), _xlfn._xlws.FILTER($E$7:$E$4572,$L$7:$L$4572<>"X"), "", 0, -1 )} -> TRUE | AI38: =IF($AH38,IF(OR($R38="B",$R38="C"),"YES",IF($R38="",IF(OR($I38="B",$I38="C"),"YES",""),"")),"")
A39: =A38+1 -> 33 | B39: =MID(E39, FIND("-", E39) + 1, 4) -> 5.10 | C39: PAS IMM PMR | D39: MSS | E39: LTIA-5.10-VIETUR-70000-RFA-MSS-0153 | F39: =IF($U39=0,$T39+22,$U39+21) -> 45698 | G39: Request for approval of method statement installation of the public address system, immigration system, professional mobile radio | H39: Đề nghị phê duyệt thuyết minh biện pháp thi công lắp đặt hệ thống phát thanh công cộng, công an cửa khẩu, bộ đàm | I39: A | J39: =MAX(0, IF(ISBLANK($W39), _xlfn.DAYS($J$1,$U39), _xlfn.DAYS($W39,$U39))) -> 29 | K39: =IF(($J39-21)>0,$J39-21,0) -> 8 | M39: Link | N39: Link | O39: Link | P39: Link | Q39: Link | R39: A | S39: 45677 | T39: 45677 | U39: 45677 | V39: 45692 | W39: 45706 | X39: Mr Phong + Shimada | Y39: 45730 | Z39: 45737 | AA39: =IF(AND($R39="",$I39=""),"",IF(OR($R39="B",$R39="C"),IF($Z39<>"",$Z39+7,IF($Y39<>"",$Y39+8,"")),IF($R39="",IF(OR($I39="B",$I39="C"),IF($W39<>"",$W39+7,IF($V39<>"",$V39+8,""))),""))) | AC39: =IF(OR($R39="B",$R39="C"),IF($AA39="","",IF($AB39="",IF($AA39>=$J$1,"In progress","Not submit yet"),IF($AA39>=$AB39,"Timely Response","Late Resubmission"))),"") | AD39: =IF(AC39="Late Resubmission",IF(AB39="","",AB39-AA39),IF(AC39="Not submit yet",IF(AA39="","",$J$1-AA39),"")) | AG39: =IF(AND(RIGHT($E39,1)>="A",RIGHT($E39,1)<="Z"),LEFT($E39,LEN($E39)-1),$E39) -> LTIA-5.10-VIETUR-70000-RFA-MSS-0153 | AH39: {=$E39=_xlfn.XLOOKUP( AG39, _xlfn._xlws.FILTER($AG$7:$AG$4572,$L$7:$L$4572<>"X"), _xlfn._xlws.FILTER($E$7:$E$4572,$L$7:$L$4572<>"X"), "", 0, -1 )} -> TRUE | AI39: =IF($AH39,IF(OR($R39="B",$R39="C"),"YES",IF($R39="",IF(OR($I39="B",$I39="C"),"YES",""),"")),"")
A40: =A39+1 -> 34 | B40: =MID(E40, FIND("-", E40) + 1, 4) -> 5.10 | C40: FAS | D40: MAS | E40: LTIA-5.10-VIETUR-70000-RFA-MAS-0468 | F40: =IF($U40=0,$T40+22,$U40+21) -> 45713 | G40: Request for approval additional of fire alarm equipment for fire alarm system | H40: Đề nghị phê duyệt bổ sung thiết bị báo cháy cho hệ thống báo cháy | I40: A | J40: =MAX(0, IF(ISBLANK($W40), _xlfn.DAYS($J$1,$U40), _xlfn.DAYS($W40,$U40))) -> 8 | K40: =IF(($J40-21)>0,$J40-21,0) -> 0 | M40: Link | N40: Link | O40: Link | P40: Link | Q40: Link | R40: A | S40: 45678 | T40: 45678 | U40: 45692 | V40: 45700 | W40: 45700 | X40: Mr Phong + Kuroda | Y40: 45730 | Z40: 45737 | AA40: =IF(AND($R40="",$I40=""),"",IF(OR($R40="B",$R40="C"),IF($Z40<>"",$Z40+7,IF($Y40<>"",$Y40+8,"")),IF($R40="",IF(OR($I40="B",$I40="C"),IF($W40<>"",$W40+7,IF($V40<>"",$V40+8,""))),""))) | AC40: =IF(OR($R40="B",$R40="C"),IF($AA40="","",IF($AB40="",IF($AA40>=$J$1,"In progress","Not submit yet"),IF($AA40>=$AB40,"Timely Response","Late Resubmission"))),"") | AD40: =IF(AC40="Late Resubmission",IF(AB40="","",AB40-AA40),IF(AC40="Not submit yet",IF(AA40="","",$J$1-AA40),"")) | AG40: =IF(AND(RIGHT($E40,1)>="A",RIGHT($E40,1)<="Z"),LEFT($E40,LEN($E40)-1),$E40) -> LTIA-5.10-VIETUR-70000-RFA-MAS-0468 | AH40: {=$E40=_xlfn.XLOOKUP( AG40, _xlfn._xlws.FILTER($AG$7:$AG$4572,$L$7:$L$4572<>"X"), _xlfn._xlws.FILTER($E$7:$E$4572,$L$7:$L$4572<>"X"), "", 0, -1 )} -> TRUE | AI40: =IF($AH40,IF(OR($R40="B",$R40="C"),"YES",IF($R40="",IF(OR($I40="B",$I40="C"),"YES",""),"")),"")
A41: =A40+1 -> 35 | B41: =MID(E41, FIND("-", E41) + 1, 4) -> 5.10 | C41: SCS | D41: MAS | E41: LTIA-5.10-VIETUR-70000-RFA-MAS-0258B | F41: =IF($U41=0,$T41+22,$U41+21) -> 45741 | G41: Request for approval Material of structured cabling system (SCS) | H41: Đề nghị phê duyệt vật tư hệ thống cấu trúc mạng | I41: A | J41: =MAX(0, IF(ISBLANK($W41), _xlfn.DAYS($J$1,$U41), _xlfn.DAYS($W41,$U41))) -> 10 | K41: =IF(($J41-21)>0,$J41-21,0) -> 0 | M41: Link | N41: Link | O41: Link | P41: Link | Q41: Link | R41: A | S41: 45719 | T41: 45719 | U41: 45720 | V41: 45729 | W41: 45730 | X41: Mr Phong + Kuroda | Y41: 45736 | Z41: 45737 | AA41: =IF(AND($R41="",$I41=""),"",IF(OR($R41="B",$R41="C"),IF($Z41<>"",$Z41+7,IF($Y41<>"",$Y41+8,"")),IF($R41="",IF(OR($I41="B",$I41="C"),IF($W41<>"",$W41+7,IF($V41<>"",$V41+8,""))),""))) | AC41: =IF(OR($R41="B",$R41="C"),IF($AA41="","",IF($AB41="",IF($AA41>=$J$1,"In progress","Not submit yet"),IF($AA41>=$AB41,"Timely Response","Late Resubmission"))),"") | AD41: =IF(AC41="Late Resubmission",IF(AB41="","",AB41-AA41),IF(AC41="Not submit yet",IF(AA41="","",$J$1-AA41),"")) | AG41: =IF(AND(RIGHT($E41,1)>="A",RIGHT($E41,1)<="Z"),LEFT($E41,LEN($E41)-1),$E41) -> LTIA-5.10-VIETUR-70000-RFA-MAS-0258 | AH41: {=$E41=_xlfn.XLOOKUP( AG41, _xlfn._xlws.FILTER($AG$7:$AG$4572,$L$7:$L$4572<>"X"), _xlfn._xlws.FILTER($E$7:$E$4572,$L$7:$L$4572<>"X"), "", 0, -1 )} -> TRUE | AI41: =IF($AH41,IF(OR($R41="B",$R41="C"),"YES",IF($R41="",IF(OR($I41="B",$I41="C"),"YES",""),"")),"")
A42: =A41+1 -> 36 | B42: =MID(E42, FIND("-", E42) + 1, 4) -> 5.10 | C42: FAS | D42: MAS | E42: LTIA-5.10-VIETUR-70000-RFA-MAS-0519 | F42: =IF($U42=0,$T42+22,$U42+21) -> 45770 | G42: Request for approval additional material cable fire resistant shield for fire alarm system (Norden) | H42: Đề nghị phê duyệt bổ sung vật liệu cáp chống cháy cho hệ thống báo cháy (Norden) | I42: A | J42: =MAX(0, IF(ISBLANK($W42), _xlfn.DAYS($J$1,$U42), _xlfn.DAYS($W42,$U42))) -> 7 | K42: =IF(($J42-21)>0,$J42-21,0) -> 0 | M42: Link | N42: Link | O42: Link | P42: Link | Q42: Link | R42: A | S42: 45748 | T42: 45748 | U42: 45749 | V42: 45756 | W42: 45756 | X42: Mr Phong + Shimada | Y42: 45772 | Z42: 45772 | AA42: =IF(AND($R42="",$I42=""),"",IF(OR($R42="B",$R42="C"),IF($Z42<>"",$Z42+7,IF($Y42<>"",$Y42+8,"")),IF($R42="",IF(OR($I42="B",$I42="C"),IF($W42<>"",$W42+7,IF($V42<>"",$V42+8,""))),""))) | AC42: =IF(OR($R42="B",$R42="C"),IF($AA42="","",IF($AB42="",IF($AA42>=$J$1,"In progress","Not submit yet"),IF($AA42>=$AB42,"Timely Response","Late Resubmission"))),"") | AD42: =IF(AC42="Late Resubmission",IF(AB42="","",AB42-AA42),IF(AC42="Not submit yet",IF(AA42="","",$J$1-AA42),"")) | AG42: =IF(AND(RIGHT($E42,1)>="A",RIGHT($E42,1)<="Z"),LEFT($E42,LEN($E42)-1),$E42) -> LTIA-5.10-VIETUR-70000-RFA-MAS-0519 | AH42: {=$E42=_xlfn.XLOOKUP( AG42, _xlfn._xlws.FILTER($AG$7:$AG$4572,$L$7:$L$4572<>"X"), _xlfn._xlws.FILTER($E$7:$E$4572,$L$7:$L$4572<>"X"), "", 0, -1 )} -> TRUE | AI42: =IF($AH42,IF(OR($R42="B",$R42="C"),"YES",IF($R42="",IF(OR($I42="B",$I42="C"),"YES",""),"")),"")
...

Sheet RFA-SDS
A1: FOLLOW DOCUMENTS - RFA-SDS / THEO DÕI HỒ SƠ - RFA-SDS | H1: Current Date Ngày hiện tại | I1: =TODAY() -> 46309
A2: SECTION TE / HẠNG MỤC TE
A4: TT | B4: Package | C4: System Hệ | D4: Document Reference No. Tham chiếu hồ sơ số | E4: Deadline to responde Thời hạn trả lời | F4: Subject | G4: Tiêu đề | H4: Status Tình trạng | I4: Processing Time Thời gian xử lý | J4: Delay Chậm trễ | K4: Withdraw or Change (X) See notes Thu hồi hoặc Thay đổi (X) Xem ghi chú | L4: Documents Submission Hồ sơ đệ trình | N4: JCJV's Response Phản hồi của JCJV | P4: Employer's Response Phản hồi của Chủ đầu tư | R4: Documents Submission Hồ sơ đệ trình | U4: JCJV's Response Phản hồi của JCJV | X4: Employer's Response Phản hồi của Chủ đầu tư | Z4: Vietur Resubmission Status Tình trạng đệ trình lại hồ sơ | AD4: Notes Ghi chú
L5: Official Chính thức | M5: Internal Nội bộ | N5: Official Chính thức | O5: Internal Nội bộ | P5: Official Chính thức | Q5: Status Trạng thái | R5: Sub. Date (Soft copy) Ngày đệ trình (bản mềm) | S5: Sub. Date (by Email) Ngày đệ trình (bằng Email) | T5: Sub. Date (Hard copy) Ngày đệ trình (bản cứng) | U5: Response Date Ngày phản hồi | V5: Submit Date Ngày phát hành | W5: Signed by Đã ký bởi | X5: Response Date Ngày phản hồi (by Email) | Y5: Submit Date (Hard copy) Ngày phát hành (bản cứng) | Z5: Deadline to resubmit Hạn chót đệ trình lại | AA5: Actual resubmission Date Ngày đệ trình thực tế | AB5: Resubmission Status Assessment Đánh giá tình trạng đệ trình lại | AC5: Delayed Days Ngày chậm trễ | AG5: Base Reference Tham chiếu cơ sở | AH5: Latest Revision Phiên bản cuối | AI5: Need Submisson Cần đệ trình lại
